Traceback (most recent call last):
  File "/Users/theo/research/whoi-climate-tutorial_2025/envs/lib/python3.11/site-packages/jupyter_cache/executors/utils.py", line 58, in single_nb_execution
    executenb(
  File "/Users/theo/research/whoi-climate-tutorial_2025/envs/lib/python3.11/site-packages/nbclient/client.py", line 1319, in execute
    return NotebookClient(nb=nb, resources=resources, km=km, **kwargs).execute()
           ^^^^^^^^^^^^^^^^^^^^^^^^^^^^^^^^^^^^^^^^^^^^^^^^^^^^^^^^^^^^^^^^^^^^^
  File "/Users/theo/research/whoi-climate-tutorial_2025/envs/lib/python3.11/site-packages/jupyter_core/utils/__init__.py", line 165, in wrapped
    return loop.run_until_complete(inner)
           ^^^^^^^^^^^^^^^^^^^^^^^^^^^^^^
  File "/Users/theo/research/whoi-climate-tutorial_2025/envs/lib/python3.11/asyncio/base_events.py", line 654, in run_until_complete
    return future.result()
           ^^^^^^^^^^^^^^^
  File "/Users/theo/research/whoi-climate-tutorial_2025/envs/lib/python3.11/site-packages/nbclient/client.py", line 709, in async_execute
    await self.async_execute_cell(
  File "/Users/theo/research/whoi-climate-tutorial_2025/envs/lib/python3.11/site-packages/nbclient/client.py", line 1062, in async_execute_cell
    await self._check_raise_for_error(cell, cell_index, exec_reply)
  File "/Users/theo/research/whoi-climate-tutorial_2025/envs/lib/python3.11/site-packages/nbclient/client.py", line 918, in _check_raise_for_error
    raise CellExecutionError.from_cell_and_msg(cell, exec_reply_content)
nbclient.exceptions.CellExecutionError: An error occurred while executing the following cell:
------------------
## specify lat/lon range
lonlat_vals = dict(lon=slice(285, 295), lat=slice(35, 45))

## trim in lon/lat space
data_ = data["TREFHT"].sel(lonlat_vals)
------------------


[31m---------------------------------------------------------------------------[39m
[31mNameError[39m                                 Traceback (most recent call last)
[36mCell[39m[36m [39m[32mIn[7][39m[32m, line 5[39m
[32m      2[39m lonlat_vals = [38;5;28mdict[39m(lon=[38;5;28mslice[39m([32m285[39m, [32m295[39m), lat=[38;5;28mslice[39m([32m35[39m, [32m45[39m))
[32m      4[39m [38;5;66;03m## trim in lon/lat space[39;00m
[32m----> [39m[32m5[39m data_ = [43mdata[49m[[33m"[39m[33mTREFHT[39m[33m"[39m].sel(lonlat_vals)

[31mNameError[39m: name 'data' is not defined

