Traceback (most recent call last):
  File "/Users/theo/research/whoi-climate-tutorial_2025/envs/lib/python3.11/site-packages/jupyter_cache/executors/utils.py", line 58, in single_nb_execution
    executenb(
  File "/Users/theo/research/whoi-climate-tutorial_2025/envs/lib/python3.11/site-packages/nbclient/client.py", line 1319, in execute
    return NotebookClient(nb=nb, resources=resources, km=km, **kwargs).execute()
           ^^^^^^^^^^^^^^^^^^^^^^^^^^^^^^^^^^^^^^^^^^^^^^^^^^^^^^^^^^^^^^^^^^^^^
  File "/Users/theo/research/whoi-climate-tutorial_2025/envs/lib/python3.11/site-packages/jupyter_core/utils/__init__.py", line 165, in wrapped
    return loop.run_until_complete(inner)
           ^^^^^^^^^^^^^^^^^^^^^^^^^^^^^^
  File "/Users/theo/research/whoi-climate-tutorial_2025/envs/lib/python3.11/asyncio/base_events.py", line 654, in run_until_complete
    return future.result()
           ^^^^^^^^^^^^^^^
  File "/Users/theo/research/whoi-climate-tutorial_2025/envs/lib/python3.11/site-packages/nbclient/client.py", line 709, in async_execute
    await self.async_execute_cell(
  File "/Users/theo/research/whoi-climate-tutorial_2025/envs/lib/python3.11/site-packages/nbclient/client.py", line 1062, in async_execute_cell
    await self._check_raise_for_error(cell, cell_index, exec_reply)
  File "/Users/theo/research/whoi-climate-tutorial_2025/envs/lib/python3.11/site-packages/nbclient/client.py", line 918, in _check_raise_for_error
    raise CellExecutionError.from_cell_and_msg(cell, exec_reply_content)
nbclient.exceptions.CellExecutionError: An error occurred while executing the following cell:
------------------
t2m = xr.open_mfdataset(t2m_files)["t2m"]
------------------


[31m---------------------------------------------------------------------------[39m
[31mOSError[39m                                   Traceback (most recent call last)
[36mCell[39m[36m [39m[32mIn[4][39m[32m, line 1[39m
[32m----> [39m[32m1[39m t2m = [43mxr[49m[43m.[49m[43mopen_mfdataset[49m[43m([49m[43mt2m_files[49m[43m)[49m[[33m"[39m[33mt2m[39m[33m"[39m]

[36mFile [39m[32m~/research/whoi-climate-tutorial_2025/envs/lib/python3.11/site-packages/xarray/backends/api.py:1597[39m, in [36mopen_mfdataset[39m[34m(paths, chunks, concat_dim, compat, preprocess, engine, data_vars, coords, combine, parallel, join, attrs_file, combine_attrs, **kwargs)[39m
[32m   1594[39m paths = _find_absolute_paths(paths, engine=engine, **kwargs)
[32m   1596[39m [38;5;28;01mif[39;00m [38;5;129;01mnot[39;00m paths:
[32m-> [39m[32m1597[39m     [38;5;28;01mraise[39;00m [38;5;167;01mOSError[39;00m([33m"[39m[33mno files to open[39m[33m"[39m)
[32m   1599[39m paths1d: [38;5;28mlist[39m[[38;5;28mstr[39m | ReadBuffer]
[32m   1600[39m [38;5;28;01mif[39;00m combine == [33m"[39m[33mnested[39m[33m"[39m:

[31mOSError[39m: no files to open

